Traceback (most recent call last):
  File "/Users/alinaxu/opt/anaconda3/lib/python3.9/site-packages/jupyter_cache/executors/utils.py", line 58, in single_nb_execution
    executenb(
  File "/Users/alinaxu/opt/anaconda3/lib/python3.9/site-packages/nbclient/client.py", line 1204, in execute
    return NotebookClient(nb=nb, resources=resources, km=km, **kwargs).execute()
  File "/Users/alinaxu/opt/anaconda3/lib/python3.9/site-packages/nbclient/util.py", line 84, in wrapped
    return just_run(coro(*args, **kwargs))
  File "/Users/alinaxu/opt/anaconda3/lib/python3.9/site-packages/nbclient/util.py", line 62, in just_run
    return loop.run_until_complete(coro)
  File "/Users/alinaxu/opt/anaconda3/lib/python3.9/asyncio/base_events.py", line 647, in run_until_complete
    return future.result()
  File "/Users/alinaxu/opt/anaconda3/lib/python3.9/site-packages/nbclient/client.py", line 663, in async_execute
    await self.async_execute_cell(
  File "/Users/alinaxu/opt/anaconda3/lib/python3.9/site-packages/nbclient/client.py", line 965, in async_execute_cell
    await self._check_raise_for_error(cell, cell_index, exec_reply)
  File "/Users/alinaxu/opt/anaconda3/lib/python3.9/site-packages/nbclient/client.py", line 862, in _check_raise_for_error
    raise CellExecutionError.from_cell_and_msg(cell, exec_reply_content)
nbclient.exceptions.CellExecutionError: An error occurred while executing the following cell:
------------------
import os
import numpy as np
from utils import *
from synthetic_datasets import *
seed = 1234
np.random.seed(seed)
d = 8
n = 300
ground_truth_G = simulate_random_dag(d=d, degree=2, graph_type='erdos-renyi', w_range = (1.0, 1.0))
c = np.zeros(d)
s = np.ones([d])
df = simulate_lsem(G = ground_truth_G, A_type ='Gaussian', n = n, baseline=0).reshape((n,d))

#plot true causal graph:
plot_net(nx.to_numpy_array(ground_truth_G), labels_name=list(range(d))) 
------------------

[0;31m---------------------------------------------------------------------------[0m
[0;31mModuleNotFoundError[0m                       Traceback (most recent call last)
[0;32m/var/folders/9j/vb5nb4rd5bx0gr1q5ytx9q600000gn/T/ipykernel_54613/2370726509.py[0m in [0;36m<module>[0;34m[0m
[1;32m      2[0m [0;32mimport[0m [0mnumpy[0m [0;32mas[0m [0mnp[0m[0;34m[0m[0;34m[0m[0m
[1;32m      3[0m [0;32mfrom[0m [0mutils[0m [0;32mimport[0m [0;34m*[0m[0;34m[0m[0;34m[0m[0m
[0;32m----> 4[0;31m [0;32mfrom[0m [0msynthetic_datasets[0m [0;32mimport[0m [0;34m*[0m[0;34m[0m[0;34m[0m[0m
[0m[1;32m      5[0m [0mseed[0m [0;34m=[0m [0;36m1234[0m[0;34m[0m[0;34m[0m[0m
[1;32m      6[0m [0mnp[0m[0;34m.[0m[0mrandom[0m[0;34m.[0m[0mseed[0m[0;34m([0m[0mseed[0m[0;34m)[0m[0;34m[0m[0;34m[0m[0m

[0;31mModuleNotFoundError[0m: No module named 'synthetic_datasets'
ModuleNotFoundError: No module named 'synthetic_datasets'

