Traceback (most recent call last):
  File "D:\anaconda3\lib\site-packages\jupyter_cache\executors\utils.py", line 58, in single_nb_execution
    executenb(
  File "D:\anaconda3\lib\site-packages\nbclient\client.py", line 1204, in execute
    return NotebookClient(nb=nb, resources=resources, km=km, **kwargs).execute()
  File "D:\anaconda3\lib\site-packages\nbclient\util.py", line 84, in wrapped
    return just_run(coro(*args, **kwargs))
  File "D:\anaconda3\lib\site-packages\nbclient\util.py", line 62, in just_run
    return loop.run_until_complete(coro)
  File "D:\anaconda3\lib\asyncio\base_events.py", line 647, in run_until_complete
    return future.result()
  File "D:\anaconda3\lib\site-packages\nbclient\client.py", line 663, in async_execute
    await self.async_execute_cell(
  File "D:\anaconda3\lib\site-packages\nbclient\client.py", line 965, in async_execute_cell
    await self._check_raise_for_error(cell, cell_index, exec_reply)
  File "D:\anaconda3\lib\site-packages\nbclient\client.py", line 862, in _check_raise_for_error
    raise CellExecutionError.from_cell_and_msg(cell, exec_reply_content)
nbclient.exceptions.CellExecutionError: An error occurred while executing the following cell:
------------------
# code used to import the learner
from causaldm.learners import ALearning
from causaldm.test import shared_simulation
import numpy as np
------------------

[1;31m---------------------------------------------------------------------------[0m
[1;31mImportError[0m                               Traceback (most recent call last)
Input [1;32mIn [1][0m, in [0;36m<cell line: 2>[1;34m()[0m
[0;32m      1[0m [38;5;66;03m# code used to import the learner[39;00m
[1;32m----> 2[0m [38;5;28;01mfrom[39;00m [38;5;21;01mcausaldm[39;00m[38;5;21;01m.[39;00m[38;5;21;01mlearners[39;00m [38;5;28;01mimport[39;00m ALearning
[0;32m      3[0m [38;5;28;01mfrom[39;00m [38;5;21;01mcausaldm[39;00m[38;5;21;01m.[39;00m[38;5;21;01mtest[39;00m [38;5;28;01mimport[39;00m shared_simulation
[0;32m      4[0m [38;5;28;01mimport[39;00m [38;5;21;01mnumpy[39;00m [38;5;28;01mas[39;00m [38;5;21;01mnp[39;00m

[1;31mImportError[0m: cannot import name 'ALearning' from 'causaldm.learners' (D:\anaconda3\lib\site-packages\causaldm\learners\__init__.py)
ImportError: cannot import name 'ALearning' from 'causaldm.learners' (D:\anaconda3\lib\site-packages\causaldm\learners\__init__.py)

