Traceback (most recent call last):
  File "D:\Anaconda\lib\site-packages\jupyter_cache\executors\utils.py", line 51, in single_nb_execution
    executenb(
  File "D:\Anaconda\lib\site-packages\nbclient\client.py", line 1112, in execute
    return NotebookClient(nb=nb, resources=resources, km=km, **kwargs).execute()
  File "D:\Anaconda\lib\site-packages\nbclient\util.py", line 74, in wrapped
    return just_run(coro(*args, **kwargs))
  File "D:\Anaconda\lib\site-packages\nbclient\util.py", line 53, in just_run
    return loop.run_until_complete(coro)
  File "D:\Anaconda\lib\asyncio\base_events.py", line 642, in run_until_complete
    return future.result()
  File "D:\Anaconda\lib\site-packages\nbclient\client.py", line 553, in async_execute
    await self.async_execute_cell(
  File "D:\Anaconda\lib\site-packages\nbclient\client.py", line 857, in async_execute_cell
    self._check_raise_for_error(cell, exec_reply)
  File "D:\Anaconda\lib\site-packages\nbclient\client.py", line 760, in _check_raise_for_error
    raise CellExecutionError.from_cell_and_msg(cell, exec_reply_content)
nbclient.exceptions.CellExecutionError: An error occurred while executing the following cell:
------------------
# code used to import the learner
from causaldm.learners import ALearning
from causaldm.test import shared_simulation
import numpy as np
------------------

[1;31m---------------------------------------------------------------------------[0m
[1;31mModuleNotFoundError[0m                       Traceback (most recent call last)
[1;32m~\AppData\Local\Temp/ipykernel_23184/261550316.py[0m in [0;36m<module>[1;34m[0m
[0;32m      1[0m [1;31m# code used to import the learner[0m[1;33m[0m[1;33m[0m[0m
[1;32m----> 2[1;33m [1;32mfrom[0m [0mcausaldm[0m[1;33m.[0m[0mlearners[0m [1;32mimport[0m [0mALearning[0m[1;33m[0m[1;33m[0m[0m
[0m[0;32m      3[0m [1;32mfrom[0m [0mcausaldm[0m[1;33m.[0m[0mtest[0m [1;32mimport[0m [0mshared_simulation[0m[1;33m[0m[1;33m[0m[0m
[0;32m      4[0m [1;32mimport[0m [0mnumpy[0m [1;32mas[0m [0mnp[0m[1;33m[0m[1;33m[0m[0m

[1;31mModuleNotFoundError[0m: No module named 'causaldm'
ModuleNotFoundError: No module named 'causaldm'

