Traceback (most recent call last):
  File "C:\Users\Yang Xu\AppData\Roaming\Python\Python37\site-packages\jupyter_cache\executors\utils.py", line 56, in single_nb_execution
    record_timing=False,
  File "C:\Users\Yang Xu\AppData\Roaming\Python\Python37\site-packages\nbclient\client.py", line 1204, in execute
    return NotebookClient(nb=nb, resources=resources, km=km, **kwargs).execute()
  File "C:\Users\Yang Xu\AppData\Roaming\Python\Python37\site-packages\nbclient\util.py", line 84, in wrapped
    return just_run(coro(*args, **kwargs))
  File "C:\Users\Yang Xu\AppData\Roaming\Python\Python37\site-packages\nbclient\util.py", line 62, in just_run
    return loop.run_until_complete(coro)
  File "C:\FAKED\Anaconda\lib\asyncio\base_events.py", line 579, in run_until_complete
    return future.result()
  File "C:\Users\Yang Xu\AppData\Roaming\Python\Python37\site-packages\nbclient\client.py", line 664, in async_execute
    cell, index, execution_count=self.code_cells_executed + 1
  File "C:\Users\Yang Xu\AppData\Roaming\Python\Python37\site-packages\nbclient\client.py", line 965, in async_execute_cell
    await self._check_raise_for_error(cell, cell_index, exec_reply)
  File "C:\Users\Yang Xu\AppData\Roaming\Python\Python37\site-packages\nbclient\client.py", line 862, in _check_raise_for_error
    raise CellExecutionError.from_cell_and_msg(cell, exec_reply_content)
nbclient.exceptions.CellExecutionError: An error occurred while executing the following cell:
------------------
##### Import Packages 
from causaldm.learners.Causal_Discovery_Learning.utils import *
from causaldm.learners.Case_Study.MIMIC3 import *
from numpy.random import randn
from random import seed as rseed
from numpy.random import seed as npseed
------------------

[1;31m---------------------------------------------------------------------------[0m
[1;31mModuleNotFoundError[0m                       Traceback (most recent call last)
[1;32m<ipython-input-3-9c014b9e403f>[0m in [0;36m<module>[1;34m[0m
[0;32m      1[0m [1;31m##### Import Packages[0m[1;33m[0m[1;33m[0m[1;33m[0m[0m
[1;32m----> 2[1;33m [1;32mfrom[0m [0mcausaldm[0m[1;33m.[0m[0mlearners[0m[1;33m.[0m[0mCausal_Discovery_Learning[0m[1;33m.[0m[0mutils[0m [1;32mimport[0m [1;33m*[0m[1;33m[0m[1;33m[0m[0m
[0m[0;32m      3[0m [1;32mfrom[0m [0mcausaldm[0m[1;33m.[0m[0mlearners[0m[1;33m.[0m[0mCase_Study[0m[1;33m.[0m[0mMIMIC3[0m [1;32mimport[0m [1;33m*[0m[1;33m[0m[1;33m[0m[0m
[0;32m      4[0m [1;32mfrom[0m [0mnumpy[0m[1;33m.[0m[0mrandom[0m [1;32mimport[0m [0mrandn[0m[1;33m[0m[1;33m[0m[0m
[0;32m      5[0m [1;32mfrom[0m [0mrandom[0m [1;32mimport[0m [0mseed[0m [1;32mas[0m [0mrseed[0m[1;33m[0m[1;33m[0m[0m

[1;31mModuleNotFoundError[0m: No module named 'causaldm'
ModuleNotFoundError: No module named 'causaldm'

