Traceback (most recent call last):
  File "/Users/wrunzhe/anaconda3/lib/python3.11/site-packages/jupyter_cache/executors/utils.py", line 58, in single_nb_execution
    executenb(
  File "/Users/wrunzhe/anaconda3/lib/python3.11/site-packages/nbclient/client.py", line 1204, in execute
    return NotebookClient(nb=nb, resources=resources, km=km, **kwargs).execute()
           ^^^^^^^^^^^^^^^^^^^^^^^^^^^^^^^^^^^^^^^^^^^^^^^^^^^^^^^^^^^^^^^^^^^^^
  File "/Users/wrunzhe/anaconda3/lib/python3.11/site-packages/nbclient/util.py", line 84, in wrapped
    return just_run(coro(*args, **kwargs))
           ^^^^^^^^^^^^^^^^^^^^^^^^^^^^^^^
  File "/Users/wrunzhe/anaconda3/lib/python3.11/site-packages/nbclient/util.py", line 62, in just_run
    return loop.run_until_complete(coro)
           ^^^^^^^^^^^^^^^^^^^^^^^^^^^^^
  File "/Users/wrunzhe/anaconda3/lib/python3.11/asyncio/base_events.py", line 653, in run_until_complete
    return future.result()
           ^^^^^^^^^^^^^^^
  File "/Users/wrunzhe/anaconda3/lib/python3.11/site-packages/nbclient/client.py", line 663, in async_execute
    await self.async_execute_cell(
  File "/Users/wrunzhe/anaconda3/lib/python3.11/site-packages/nbclient/client.py", line 965, in async_execute_cell
    await self._check_raise_for_error(cell, cell_index, exec_reply)
  File "/Users/wrunzhe/anaconda3/lib/python3.11/site-packages/nbclient/client.py", line 862, in _check_raise_for_error
    raise CellExecutionError.from_cell_and_msg(cell, exec_reply_content)
nbclient.exceptions.CellExecutionError: An error occurred while executing the following cell:
------------------
import os
os.chdir('D:/GitHub/CausalDM')
import pandas as pd
import pickle
import numpy as np
import pandas as pd
file = open('./causaldm/MIMIC3/mimic3_MDTR_data_dict_3stage_V2.pickle', 'rb')
mimic3_MDTR = pickle.load(file)
state, action, mediator, reward = mimic3_MDTR.values()
reward.iloc[np.where(reward['Died_within_48H']==-1)[0],-1]=0 # change the discrete action to binary
MDTR_data = pd.read_csv('./causaldm/MIMIC3/mimic3_MDTR_3stage_V2.csv')
MDTR_data.iloc[np.where(MDTR_data['Died_within_48H']==-1)[0],-1]=0
MDTR_data.head()
------------------

[0;31m---------------------------------------------------------------------------[0m
[0;31mFileNotFoundError[0m                         Traceback (most recent call last)
Cell [0;32mIn[1], line 2[0m
[1;32m      1[0m [38;5;28;01mimport[39;00m [38;5;21;01mos[39;00m
[0;32m----> 2[0m os[38;5;241m.[39mchdir([38;5;124m'[39m[38;5;124mD:/GitHub/CausalDM[39m[38;5;124m'[39m)
[1;32m      3[0m [38;5;28;01mimport[39;00m [38;5;21;01mpandas[39;00m [38;5;28;01mas[39;00m [38;5;21;01mpd[39;00m
[1;32m      4[0m [38;5;28;01mimport[39;00m [38;5;21;01mpickle[39;00m

[0;31mFileNotFoundError[0m: [Errno 2] No such file or directory: 'D:/GitHub/CausalDM'
FileNotFoundError: [Errno 2] No such file or directory: 'D:/GitHub/CausalDM'

