Traceback (most recent call last):
  File "/Users/alinaxu/opt/anaconda3/lib/python3.9/site-packages/jupyter_cache/executors/utils.py", line 58, in single_nb_execution
    executenb(
  File "/Users/alinaxu/opt/anaconda3/lib/python3.9/site-packages/nbclient/client.py", line 1204, in execute
    return NotebookClient(nb=nb, resources=resources, km=km, **kwargs).execute()
  File "/Users/alinaxu/opt/anaconda3/lib/python3.9/site-packages/nbclient/util.py", line 84, in wrapped
    return just_run(coro(*args, **kwargs))
  File "/Users/alinaxu/opt/anaconda3/lib/python3.9/site-packages/nbclient/util.py", line 62, in just_run
    return loop.run_until_complete(coro)
  File "/Users/alinaxu/opt/anaconda3/lib/python3.9/asyncio/base_events.py", line 647, in run_until_complete
    return future.result()
  File "/Users/alinaxu/opt/anaconda3/lib/python3.9/site-packages/nbclient/client.py", line 663, in async_execute
    await self.async_execute_cell(
  File "/Users/alinaxu/opt/anaconda3/lib/python3.9/site-packages/nbclient/client.py", line 965, in async_execute_cell
    await self._check_raise_for_error(cell, cell_index, exec_reply)
  File "/Users/alinaxu/opt/anaconda3/lib/python3.9/site-packages/nbclient/client.py", line 862, in _check_raise_for_error
    raise CellExecutionError.from_cell_and_msg(cell, exec_reply_content)
nbclient.exceptions.CellExecutionError: An error occurred while executing the following cell:
------------------
# ----------- Estimated DAG based on NOTEARS 

mimic3_data_final = mimic3_data  

selected = ['Glucose', 'PaO2_FiO2', 'IV Input', 'SOFA', 'SOFA Post', 'Died within 48H']

sample_demo = mimic3_data_final[selected]
est_mt = notears_linear(np.array(sample_demo), lambda1=0, loss_type='l2',w_threshold=0.1)
 
# ----------- Refit Associated Matrix under LSEM 

est_mt, _ = refit(sample_demo, est_mt, selected) 
------------------

[0;31m---------------------------------------------------------------------------[0m
[0;31mKeyError[0m                                  Traceback (most recent call last)
[0;32m/var/folders/9j/vb5nb4rd5bx0gr1q5ytx9q600000gn/T/ipykernel_69660/2233535502.py[0m in [0;36m<module>[0;34m[0m
[1;32m      5[0m [0mselected[0m [0;34m=[0m [0;34m[[0m[0;34m'Glucose'[0m[0;34m,[0m [0;34m'PaO2_FiO2'[0m[0;34m,[0m [0;34m'IV Input'[0m[0;34m,[0m [0;34m'SOFA'[0m[0;34m,[0m [0;34m'SOFA Post'[0m[0;34m,[0m [0;34m'Died within 48H'[0m[0;34m][0m[0;34m[0m[0;34m[0m[0m
[1;32m      6[0m [0;34m[0m[0m
[0;32m----> 7[0;31m [0msample_demo[0m [0;34m=[0m [0mmimic3_data_final[0m[0;34m[[0m[0mselected[0m[0;34m][0m[0;34m[0m[0;34m[0m[0m
[0m[1;32m      8[0m [0mest_mt[0m [0;34m=[0m [0mnotears_linear[0m[0;34m([0m[0mnp[0m[0;34m.[0m[0marray[0m[0;34m([0m[0msample_demo[0m[0;34m)[0m[0;34m,[0m [0mlambda1[0m[0;34m=[0m[0;36m0[0m[0;34m,[0m [0mloss_type[0m[0;34m=[0m[0;34m'l2'[0m[0;34m,[0m[0mw_threshold[0m[0;34m=[0m[0;36m0.1[0m[0;34m)[0m[0;34m[0m[0;34m[0m[0m
[1;32m      9[0m [0;34m[0m[0m

[0;32m~/opt/anaconda3/lib/python3.9/site-packages/pandas/core/frame.py[0m in [0;36m__getitem__[0;34m(self, key)[0m
[1;32m   3509[0m             [0;32mif[0m [0mis_iterator[0m[0;34m([0m[0mkey[0m[0;34m)[0m[0;34m:[0m[0;34m[0m[0;34m[0m[0m
[1;32m   3510[0m                 [0mkey[0m [0;34m=[0m [0mlist[0m[0;34m([0m[0mkey[0m[0;34m)[0m[0;34m[0m[0;34m[0m[0m
[0;32m-> 3511[0;31m             [0mindexer[0m [0;34m=[0m [0mself[0m[0;34m.[0m[0mcolumns[0m[0;34m.[0m[0m_get_indexer_strict[0m[0;34m([0m[0mkey[0m[0;34m,[0m [0;34m"columns"[0m[0;34m)[0m[0;34m[[0m[0;36m1[0m[0;34m][0m[0;34m[0m[0;34m[0m[0m
[0m[1;32m   3512[0m [0;34m[0m[0m
[1;32m   3513[0m         [0;31m# take() does not accept boolean indexers[0m[0;34m[0m[0;34m[0m[0m

[0;32m~/opt/anaconda3/lib/python3.9/site-packages/pandas/core/indexes/base.py[0m in [0;36m_get_indexer_strict[0;34m(self, key, axis_name)[0m
[1;32m   5794[0m             [0mkeyarr[0m[0;34m,[0m [0mindexer[0m[0;34m,[0m [0mnew_indexer[0m [0;34m=[0m [0mself[0m[0;34m.[0m[0m_reindex_non_unique[0m[0;34m([0m[0mkeyarr[0m[0;34m)[0m[0;34m[0m[0;34m[0m[0m
[1;32m   5795[0m [0;34m[0m[0m
[0;32m-> 5796[0;31m         [0mself[0m[0;34m.[0m[0m_raise_if_missing[0m[0;34m([0m[0mkeyarr[0m[0;34m,[0m [0mindexer[0m[0;34m,[0m [0maxis_name[0m[0;34m)[0m[0;34m[0m[0;34m[0m[0m
[0m[1;32m   5797[0m [0;34m[0m[0m
[1;32m   5798[0m         [0mkeyarr[0m [0;34m=[0m [0mself[0m[0;34m.[0m[0mtake[0m[0;34m([0m[0mindexer[0m[0;34m)[0m[0;34m[0m[0;34m[0m[0m

[0;32m~/opt/anaconda3/lib/python3.9/site-packages/pandas/core/indexes/base.py[0m in [0;36m_raise_if_missing[0;34m(self, key, indexer, axis_name)[0m
[1;32m   5857[0m [0;34m[0m[0m
[1;32m   5858[0m             [0mnot_found[0m [0;34m=[0m [0mlist[0m[0;34m([0m[0mensure_index[0m[0;34m([0m[0mkey[0m[0;34m)[0m[0;34m[[0m[0mmissing_mask[0m[0;34m.[0m[0mnonzero[0m[0;34m([0m[0;34m)[0m[0;34m[[0m[0;36m0[0m[0;34m][0m[0;34m][0m[0;34m.[0m[0munique[0m[0;34m([0m[0;34m)[0m[0;34m)[0m[0;34m[0m[0;34m[0m[0m
[0;32m-> 5859[0;31m             [0;32mraise[0m [0mKeyError[0m[0;34m([0m[0;34mf"{not_found} not in index"[0m[0;34m)[0m[0;34m[0m[0;34m[0m[0m
[0m[1;32m   5860[0m [0;34m[0m[0m
[1;32m   5861[0m     [0;34m@[0m[0moverload[0m[0;34m[0m[0;34m[0m[0m

[0;31mKeyError[0m: "['SOFA Post'] not in index"
KeyError: "['SOFA Post'] not in index"

