Traceback (most recent call last):
  File "D:\anaconda3\envs\BookBuilder\lib\site-packages\jupyter_cache\executors\utils.py", line 56, in single_nb_execution
    record_timing=False,
  File "D:\anaconda3\envs\BookBuilder\lib\site-packages\nbclient\client.py", line 1204, in execute
    return NotebookClient(nb=nb, resources=resources, km=km, **kwargs).execute()
  File "D:\anaconda3\envs\BookBuilder\lib\site-packages\nbclient\util.py", line 84, in wrapped
    return just_run(coro(*args, **kwargs))
  File "D:\anaconda3\envs\BookBuilder\lib\site-packages\nbclient\util.py", line 62, in just_run
    return loop.run_until_complete(coro)
  File "D:\anaconda3\envs\BookBuilder\lib\asyncio\base_events.py", line 587, in run_until_complete
    return future.result()
  File "D:\anaconda3\envs\BookBuilder\lib\site-packages\nbclient\client.py", line 664, in async_execute
    cell, index, execution_count=self.code_cells_executed + 1
  File "D:\anaconda3\envs\BookBuilder\lib\site-packages\nbclient\client.py", line 965, in async_execute_cell
    await self._check_raise_for_error(cell, cell_index, exec_reply)
  File "D:\anaconda3\envs\BookBuilder\lib\site-packages\nbclient\client.py", line 862, in _check_raise_for_error
    raise CellExecutionError.from_cell_and_msg(cell, exec_reply_content)
nbclient.exceptions.CellExecutionError: An error occurred while executing the following cell:
------------------
# A demo with code on how to use the package
from causaldm.learners import ALearning
from causaldm.test import shared_simulation
import numpy as np
------------------

[1;31m---------------------------------------------------------------------------[0m
[1;31mModuleNotFoundError[0m                       Traceback (most recent call last)
[1;32m~\AppData\Local\Temp\ipykernel_17048\3431659105.py[0m in [0;36m<module>[1;34m[0m
[0;32m      1[0m [1;31m# A demo with code on how to use the package[0m[1;33m[0m[1;33m[0m[1;33m[0m[0m
[1;32m----> 2[1;33m [1;32mfrom[0m [0mcausaldm[0m[1;33m.[0m[0mlearners[0m [1;32mimport[0m [0mALearning[0m[1;33m[0m[1;33m[0m[0m
[0m[0;32m      3[0m [1;32mfrom[0m [0mcausaldm[0m[1;33m.[0m[0mtest[0m [1;32mimport[0m [0mshared_simulation[0m[1;33m[0m[1;33m[0m[0m
[0;32m      4[0m [1;32mimport[0m [0mnumpy[0m [1;32mas[0m [0mnp[0m[1;33m[0m[1;33m[0m[0m

[1;31mModuleNotFoundError[0m: No module named 'causaldm'
ModuleNotFoundError: No module named 'causaldm'

