Traceback (most recent call last):
  File "/Users/alinaxu/opt/anaconda3/lib/python3.9/site-packages/jupyter_cache/executors/utils.py", line 58, in single_nb_execution
    executenb(
  File "/Users/alinaxu/opt/anaconda3/lib/python3.9/site-packages/nbclient/client.py", line 1204, in execute
    return NotebookClient(nb=nb, resources=resources, km=km, **kwargs).execute()
  File "/Users/alinaxu/opt/anaconda3/lib/python3.9/site-packages/nbclient/util.py", line 84, in wrapped
    return just_run(coro(*args, **kwargs))
  File "/Users/alinaxu/opt/anaconda3/lib/python3.9/site-packages/nbclient/util.py", line 62, in just_run
    return loop.run_until_complete(coro)
  File "/Users/alinaxu/opt/anaconda3/lib/python3.9/asyncio/base_events.py", line 647, in run_until_complete
    return future.result()
  File "/Users/alinaxu/opt/anaconda3/lib/python3.9/site-packages/nbclient/client.py", line 663, in async_execute
    await self.async_execute_cell(
  File "/Users/alinaxu/opt/anaconda3/lib/python3.9/site-packages/nbclient/client.py", line 965, in async_execute_cell
    await self._check_raise_for_error(cell, cell_index, exec_reply)
  File "/Users/alinaxu/opt/anaconda3/lib/python3.9/site-packages/nbclient/client.py", line 862, in _check_raise_for_error
    raise CellExecutionError.from_cell_and_msg(cell, exec_reply_content)
nbclient.exceptions.CellExecutionError: An error occurred while executing the following cell:
------------------
# initialize the learner
import os
os.chdir('/Users/alinaxu/Documents/CDM/CausalDM')
from causaldm.learners.CPL13.disc.DR_QuantileOTR import *
Quantile_OTR=QuantileOTR()

# when a=1, Y ~ 1+x1+2.5*x2
# when a=0, Y ~ 1-x1+2*x2
moCondQuant_0 = ['X_1', 'X_2']
moCondQuant_1 = ['X_1', 'X_2']
------------------

[0;31m---------------------------------------------------------------------------[0m
[0;31mNameError[0m                                 Traceback (most recent call last)
[0;32m/var/folders/9j/vb5nb4rd5bx0gr1q5ytx9q600000gn/T/ipykernel_63907/1796369087.py[0m in [0;36m<module>[0;34m[0m
[1;32m      2[0m [0;32mimport[0m [0mos[0m[0;34m[0m[0;34m[0m[0m
[1;32m      3[0m [0mos[0m[0;34m.[0m[0mchdir[0m[0;34m([0m[0;34m'/Users/alinaxu/Documents/CDM/CausalDM'[0m[0;34m)[0m[0;34m[0m[0;34m[0m[0m
[0;32m----> 4[0;31m [0;32mfrom[0m [0mcausaldm[0m[0;34m.[0m[0mlearners[0m[0;34m.[0m[0mCPL13[0m[0;34m.[0m[0mdisc[0m[0;34m.[0m[0mDR_QuantileOTR[0m [0;32mimport[0m [0;34m*[0m[0;34m[0m[0;34m[0m[0m
[0m[1;32m      5[0m [0mQuantile_OTR[0m[0;34m=[0m[0mQuantileOTR[0m[0;34m([0m[0;34m)[0m[0;34m[0m[0;34m[0m[0m
[1;32m      6[0m [0;34m[0m[0m

[0;32m~/opt/anaconda3/lib/python3.9/site-packages/causaldm/learners/CPL13/disc/DR_QuantileOTR.py[0m in [0;36m<module>[0;34m[0m
[1;32m     16[0m [0;32mimport[0m [0mstatsmodels[0m[0;34m.[0m[0mformula[0m[0;34m.[0m[0mapi[0m [0;32mas[0m [0msmf[0m[0;34m[0m[0;34m[0m[0m
[1;32m     17[0m [0;34m[0m[0m
[0;32m---> 18[0;31m [0;32mclass[0m [0mQuantileOTR[0m[0;34m([0m[0mBasePolicyLearner[0m[0;34m)[0m[0;34m:[0m[0;34m[0m[0;34m[0m[0m
[0m[1;32m     19[0m     """
[1;32m     20[0m     [0mLiterature[0m[0;34m:[0m[0;34m[0m[0;34m[0m[0m

[0;32m~/opt/anaconda3/lib/python3.9/site-packages/causaldm/learners/CPL13/disc/DR_QuantileOTR.py[0m in [0;36mQuantileOTR[0;34m()[0m
[1;32m     36[0m     """
[1;32m     37[0m [0;34m[0m[0m
[0;32m---> 38[0;31m     [0;34m@[0m[0mautoargs[0m[0;34m([0m[0;34m)[0m[0;34m[0m[0;34m[0m[0m
[0m[1;32m     39[0m     [0;32mdef[0m [0m__init__[0m[0;34m([0m[0mself[0m[0;34m)[0m[0;34m:[0m[0;34m[0m[0;34m[0m[0m
[1;32m     40[0m         [0;32mpass[0m[0;34m[0m[0;34m[0m[0m

[0;31mNameError[0m: name 'autoargs' is not defined
NameError: name 'autoargs' is not defined

