Traceback (most recent call last):
<<<<<<< Updated upstream
  File "/Users/alinaxu/opt/anaconda3/lib/python3.9/site-packages/jupyter_cache/executors/utils.py", line 58, in single_nb_execution
=======
  File "D:\anaconda3\lib\site-packages\jupyter_cache\executors\utils.py", line 58, in single_nb_execution
>>>>>>> Stashed changes
    executenb(
  File "D:\anaconda3\lib\site-packages\nbclient\client.py", line 1204, in execute
    return NotebookClient(nb=nb, resources=resources, km=km, **kwargs).execute()
  File "D:\anaconda3\lib\site-packages\nbclient\util.py", line 84, in wrapped
    return just_run(coro(*args, **kwargs))
  File "D:\anaconda3\lib\site-packages\nbclient\util.py", line 62, in just_run
    return loop.run_until_complete(coro)
  File "D:\anaconda3\lib\asyncio\base_events.py", line 647, in run_until_complete
    return future.result()
  File "D:\anaconda3\lib\site-packages\nbclient\client.py", line 663, in async_execute
    await self.async_execute_cell(
<<<<<<< Updated upstream
  File "/Users/alinaxu/opt/anaconda3/lib/python3.9/site-packages/nbclient/client.py", line 965, in async_execute_cell
    await self._check_raise_for_error(cell, cell_index, exec_reply)
  File "/Users/alinaxu/opt/anaconda3/lib/python3.9/site-packages/nbclient/client.py", line 862, in _check_raise_for_error
    raise CellExecutionError.from_cell_and_msg(cell, exec_reply_content)
nbclient.exceptions.CellExecutionError: An error occurred while executing the following cell:
------------------
# The code is available at https://github.com/claudiashi57/dragonnet
# import related packages
import numpy as np
import pandas as pd
from matplotlib import pyplot as plt;
from sklearn.ensemble import GradientBoostingRegressor
from sklearn.linear_model import LinearRegression
from causaldm.learners.CEL.Single_Stage import _env_getdata_CEL
from causaldm.learners.CEL.Single_Stage.Dragonnet import *
import warnings
warnings.filterwarnings('ignore')
------------------

[0;31m---------------------------------------------------------------------------[0m
[0;31mModuleNotFoundError[0m                       Traceback (most recent call last)
[0;32m/var/folders/9j/vb5nb4rd5bx0gr1q5ytx9q600000gn/T/ipykernel_71135/1311581033.py[0m in [0;36m<module>[0;34m[0m
[1;32m      6[0m [0;32mfrom[0m [0msklearn[0m[0;34m.[0m[0mensemble[0m [0;32mimport[0m [0mGradientBoostingRegressor[0m[0;34m[0m[0;34m[0m[0m
[1;32m      7[0m [0;32mfrom[0m [0msklearn[0m[0;34m.[0m[0mlinear_model[0m [0;32mimport[0m [0mLinearRegression[0m[0;34m[0m[0;34m[0m[0m
[0;32m----> 8[0;31m [0;32mfrom[0m [0mcausaldm[0m[0;34m.[0m[0mlearners[0m[0;34m.[0m[0mCEL[0m[0;34m.[0m[0mSingle_Stage[0m [0;32mimport[0m [0m_env_getdata_CEL[0m[0;34m[0m[0;34m[0m[0m
[0m[1;32m      9[0m [0;32mfrom[0m [0mcausaldm[0m[0;34m.[0m[0mlearners[0m[0;34m.[0m[0mCEL[0m[0;34m.[0m[0mSingle_Stage[0m[0;34m.[0m[0mDragonnet[0m [0;32mimport[0m [0;34m*[0m[0;34m[0m[0;34m[0m[0m
[1;32m     10[0m [0;32mimport[0m [0mwarnings[0m[0;34m[0m[0;34m[0m[0m

[0;32m~/Documents/CDM/CausalDM/causaldm/learners/CEL/Single_Stage/_env_getdata_CEL.py[0m in [0;36m<module>[0;34m[0m
[0;32m----> 1[0;31m [0;32mfrom[0m [0;34m.[0m[0;34m.[0m[0m_util_online[0m [0;32mimport[0m [0;34m*[0m[0;34m[0m[0;34m[0m[0m
[0m[1;32m      2[0m [0;32mimport[0m [0mos[0m[0;34m[0m[0;34m[0m[0m
[1;32m      3[0m [0;32mimport[0m [0mrandom[0m[0;34m[0m[0;34m[0m[0m
[1;32m      4[0m [0;32mimport[0m [0mpickle[0m[0;34m[0m[0;34m[0m[0m
[1;32m      5[0m [0;32mimport[0m [0mpandas[0m [0;32mas[0m [0mpd[0m[0;34m[0m[0;34m[0m[0m

[0;31mModuleNotFoundError[0m: No module named 'causaldm.learners.CEL._util_online'
ModuleNotFoundError: No module named 'causaldm.learners.CEL._util_online'
=======
  File "D:\anaconda3\lib\site-packages\nbclient\client.py", line 965, in async_execute_cell
    await self._check_raise_for_error(cell, cell_index, exec_reply)
  File "D:\anaconda3\lib\site-packages\nbclient\client.py", line 862, in _check_raise_for_error
    raise CellExecutionError.from_cell_and_msg(cell, exec_reply_content)
nbclient.exceptions.CellExecutionError: An error occurred while executing the following cell:
------------------
from IPython import display
import os
os.chdir('/Users/alinaxu/Documents/CDM/CausalDM')
display.Image("./images/CEL-SingleStage-Dragonnet.png", width=500)
------------------

[1;31m---------------------------------------------------------------------------[0m
[1;31mFileNotFoundError[0m                         Traceback (most recent call last)
Input [1;32mIn [1][0m, in [0;36m<cell line: 3>[1;34m()[0m
[0;32m      1[0m [38;5;28;01mfrom[39;00m [38;5;21;01mIPython[39;00m [38;5;28;01mimport[39;00m display
[0;32m      2[0m [38;5;28;01mimport[39;00m [38;5;21;01mos[39;00m
[1;32m----> 3[0m [43mos[49m[38;5;241;43m.[39;49m[43mchdir[49m[43m([49m[38;5;124;43m'[39;49m[38;5;124;43m/Users/alinaxu/Documents/CDM/CausalDM[39;49m[38;5;124;43m'[39;49m[43m)[49m
[0;32m      4[0m display[38;5;241m.[39mImage([38;5;124m"[39m[38;5;124m./images/CEL-SingleStage-Dragonnet.png[39m[38;5;124m"[39m, width[38;5;241m=[39m[38;5;241m500[39m)

[1;31mFileNotFoundError[0m: [WinError 3] 系统找不到指定的路径。: '/Users/alinaxu/Documents/CDM/CausalDM'
FileNotFoundError: [WinError 3] 系统找不到指定的路径。: '/Users/alinaxu/Documents/CDM/CausalDM'
>>>>>>> Stashed changes

