Traceback (most recent call last):
  File "/Users/wrunzhe/anaconda3/lib/python3.11/site-packages/jupyter_cache/executors/utils.py", line 58, in single_nb_execution
    executenb(
  File "/Users/wrunzhe/anaconda3/lib/python3.11/site-packages/nbclient/client.py", line 1204, in execute
    return NotebookClient(nb=nb, resources=resources, km=km, **kwargs).execute()
           ^^^^^^^^^^^^^^^^^^^^^^^^^^^^^^^^^^^^^^^^^^^^^^^^^^^^^^^^^^^^^^^^^^^^^
  File "/Users/wrunzhe/anaconda3/lib/python3.11/site-packages/nbclient/util.py", line 84, in wrapped
    return just_run(coro(*args, **kwargs))
           ^^^^^^^^^^^^^^^^^^^^^^^^^^^^^^^
  File "/Users/wrunzhe/anaconda3/lib/python3.11/site-packages/nbclient/util.py", line 62, in just_run
    return loop.run_until_complete(coro)
           ^^^^^^^^^^^^^^^^^^^^^^^^^^^^^
  File "/Users/wrunzhe/anaconda3/lib/python3.11/asyncio/base_events.py", line 653, in run_until_complete
    return future.result()
           ^^^^^^^^^^^^^^^
  File "/Users/wrunzhe/anaconda3/lib/python3.11/site-packages/nbclient/client.py", line 663, in async_execute
    await self.async_execute_cell(
  File "/Users/wrunzhe/anaconda3/lib/python3.11/site-packages/nbclient/client.py", line 965, in async_execute_cell
    await self._check_raise_for_error(cell, cell_index, exec_reply)
  File "/Users/wrunzhe/anaconda3/lib/python3.11/site-packages/nbclient/client.py", line 862, in _check_raise_for_error
    raise CellExecutionError.from_cell_and_msg(cell, exec_reply_content)
nbclient.exceptions.CellExecutionError: An error occurred while executing the following cell:
------------------
from IPython import display
import os
os.chdir('/Users/alinaxu/Documents/CDM/CausalDM')
display.Image("./images/CEL-Mediation-IID.png")
------------------

[0;31m---------------------------------------------------------------------------[0m
[0;31mFileNotFoundError[0m                         Traceback (most recent call last)
Cell [0;32mIn[1], line 3[0m
[1;32m      1[0m [38;5;28;01mfrom[39;00m [38;5;21;01mIPython[39;00m [38;5;28;01mimport[39;00m display
[1;32m      2[0m [38;5;28;01mimport[39;00m [38;5;21;01mos[39;00m
[0;32m----> 3[0m os[38;5;241m.[39mchdir([38;5;124m'[39m[38;5;124m/Users/alinaxu/Documents/CDM/CausalDM[39m[38;5;124m'[39m)
[1;32m      4[0m display[38;5;241m.[39mImage([38;5;124m"[39m[38;5;124m./images/CEL-Mediation-IID.png[39m[38;5;124m"[39m)

[0;31mFileNotFoundError[0m: [Errno 2] No such file or directory: '/Users/alinaxu/Documents/CDM/CausalDM'
FileNotFoundError: [Errno 2] No such file or directory: '/Users/alinaxu/Documents/CDM/CausalDM'

