Traceback (most recent call last):
  File "/Users/alinaxu/opt/anaconda3/lib/python3.9/site-packages/jupyter_cache/executors/utils.py", line 58, in single_nb_execution
    executenb(
  File "/Users/alinaxu/opt/anaconda3/lib/python3.9/site-packages/nbclient/client.py", line 1204, in execute
    return NotebookClient(nb=nb, resources=resources, km=km, **kwargs).execute()
  File "/Users/alinaxu/opt/anaconda3/lib/python3.9/site-packages/nbclient/util.py", line 84, in wrapped
    return just_run(coro(*args, **kwargs))
  File "/Users/alinaxu/opt/anaconda3/lib/python3.9/site-packages/nbclient/util.py", line 62, in just_run
    return loop.run_until_complete(coro)
  File "/Users/alinaxu/opt/anaconda3/lib/python3.9/asyncio/base_events.py", line 647, in run_until_complete
    return future.result()
  File "/Users/alinaxu/opt/anaconda3/lib/python3.9/site-packages/nbclient/client.py", line 663, in async_execute
    await self.async_execute_cell(
  File "/Users/alinaxu/opt/anaconda3/lib/python3.9/site-packages/nbclient/client.py", line 965, in async_execute_cell
    await self._check_raise_for_error(cell, cell_index, exec_reply)
  File "/Users/alinaxu/opt/anaconda3/lib/python3.9/site-packages/nbclient/client.py", line 862, in _check_raise_for_error
    raise CellExecutionError.from_cell_and_msg(cell, exec_reply_content)
nbclient.exceptions.CellExecutionError: An error occurred while executing the following cell:
------------------
# Get data
data_behavior = get_data_simulation(n, seed, policy="behavior")
#data_target = get_data_simulation(n0, seed, policy="target")

# The true expected heterogeneous treatment effect
HTE_true = get_data_simulation(n, seed, policy="1")['R']-get_data_simulation(n, seed, policy="0")['R']


------------------

[0;31m---------------------------------------------------------------------------[0m
[0;31mUnboundLocalError[0m                         Traceback (most recent call last)
[0;32m/var/folders/9j/vb5nb4rd5bx0gr1q5ytx9q600000gn/T/ipykernel_69115/2180662469.py[0m in [0;36m<module>[0;34m[0m
[1;32m      4[0m [0;34m[0m[0m
[1;32m      5[0m [0;31m# The true expected heterogeneous treatment effect[0m[0;34m[0m[0;34m[0m[0m
[0;32m----> 6[0;31m [0mHTE_true[0m [0;34m=[0m [0mget_data_simulation[0m[0;34m([0m[0mn[0m[0;34m,[0m [0mseed[0m[0;34m,[0m [0mpolicy[0m[0;34m=[0m[0;34m"1"[0m[0;34m)[0m[0;34m[[0m[0;34m'R'[0m[0;34m][0m[0;34m-[0m[0mget_data_simulation[0m[0;34m([0m[0mn[0m[0;34m,[0m [0mseed[0m[0;34m,[0m [0mpolicy[0m[0;34m=[0m[0;34m"0"[0m[0;34m)[0m[0;34m[[0m[0;34m'R'[0m[0;34m][0m[0;34m[0m[0;34m[0m[0m
[0m[1;32m      7[0m [0;34m[0m[0m

[0;32m~/opt/anaconda3/lib/python3.9/site-packages/causaldm/_util_causaldm.py[0m in [0;36mget_data_simulation[0;34m(n0, seed, policy)[0m
[1;32m    227[0m         [0mdata[0m[0;34m=[0m[0mpd[0m[0;34m.[0m[0mDataFrame[0m[0;34m([0m[0mdata[0m[0;34m)[0m[0;34m[0m[0;34m[0m[0m
[1;32m    228[0m [0;34m[0m[0m
[0;32m--> 229[0;31m     [0;32mreturn[0m [0mdata[0m[0;34m[0m[0;34m[0m[0m
[0m
[0;31mUnboundLocalError[0m: local variable 'data' referenced before assignment
UnboundLocalError: local variable 'data' referenced before assignment

